<mujoco model="mass_on_frictionless_incline">
  <!-- Single block on a frictionless 25-degree ramp.  Acceleration a = g·sin(θ)
       along the slope, independent of mass.  Slide joint keeps motion on the
       surface without contact jitter. -->
  <compiler angle="radian" coordinate="local" autolimits="true"/>
  <option timestep="0.002" gravity="0 0 -9.81" integrator="implicitfast"
          impratio="3" cone="elliptic"/>

  <visual>
    <headlight diffuse="0 0 0" ambient="0.50 0.48 0.55" specular="0 0 0"/>
    <rgba haze="0.94 0.91 0.90 1"/>
    <global azimuth="120" elevation="-15" offwidth="1920" offheight="1080" fovy="38"/>
    <quality shadowsize="8192" offsamples="8"/>
    <map shadowclip="6" shadowscale="0.7"/>
  </visual>

  <asset>
    <texture type="skybox" builtin="flat"
             rgb1="0.74 0.68 0.86" rgb2="0.74 0.68 0.86"
             width="512" height="512" mark="none" markrgb="0 0 0"/>

    <material name="floor_mat" rgba="0.94 0.91 0.90 1" specular="0" shininess="0"/>
    <material name="ramp_mat" rgba="0.86 0.71 0.42 1" specular="0.1" shininess="0.15"/>
    <material name="ramp_dark" rgba="0.70 0.55 0.30 1" specular="0.1" shininess="0.15"/>
    <material name="block_cream" rgba="0.96 0.85 0.66 1" specular="0.2" shininess="0.25"/>
  </asset>

  <worldbody>
    <light pos="0 0 12" dir="-0.30 0.55 -1" directional="true" castshadow="true"
           diffuse="0.85 0.82 0.78" specular="0.15 0.15 0.15"/>
    <light pos="0 0 8" dir="0.40 -0.30 -1" directional="true" castshadow="false"
           diffuse="0.28 0.28 0.34" specular="0 0 0"/>

    <geom name="floor" type="plane" size="40 40 0.1" material="floor_mat"/>

    <geom name="ramp" type="box" size="1.5 0.55 0.04"
          pos="0 0 0.65" euler="0 -0.4363 0"
          material="ramp_mat" friction="0 0 0"/>
    <geom type="box" size="1.5 0.012 0.018"
          pos="0 -0.55 0.69" euler="0 -0.4363 0" material="ramp_dark"/>

    <!-- Anchor at ramp top; qpos=0 at release, qpos≈−2.68 at low end. -->
    <body name="block" pos="1.221 0 1.289" euler="0 -0.4363 0">
      <joint name="slide" type="slide" axis="1 0 0"
             range="-2.75 0" damping="0"/>
      <geom type="box" size="0.06 0.06 0.05" mass="0.3"
            material="block_cream" friction="0 0 0"/>
    </body>

    <camera name="cam" pos="0.3 -3.0 1.4" fovy="38"
            xyaxes="0.995 0.100 0   -0.030 0.295 0.955"/>
  </worldbody>
</mujoco>
