<mujoco model="inverted_pendulum_tower">
  <!-- Stack of 4 inverted pendulum links.  Start vertical, brief wobble, then collapse.
       Render 4 s:
         --kick-at 0.55 --kick-qvel "0.10,0,0,0"
       (impulse on bottom hinge h0 after ~0.55 s hold). -->
  <compiler angle="radian" coordinate="local" autolimits="true"/>
  <option timestep="0.001" gravity="0 0 -9.81" integrator="implicitfast"/>

  <visual>
    <headlight diffuse="0 0 0" ambient="0.50 0.48 0.55" specular="0 0 0"/>
    <rgba haze="0.94 0.91 0.90 1"/>
    <global azimuth="120" elevation="-15" offwidth="1920" offheight="1080" fovy="38"/>
    <quality shadowsize="8192" offsamples="8"/>
    <map shadowclip="6" shadowscale="0.7"/>
  </visual>

  <asset>
    <texture type="skybox" builtin="flat"
             rgb1="0.74 0.68 0.86" rgb2="0.74 0.68 0.86"
             width="512" height="512" mark="none" markrgb="0 0 0"/>
    <material name="floor_mat" rgba="0.94 0.91 0.90 1" specular="0" shininess="0"/>
    <material name="base_mat" rgba="0.78 0.65 0.40 1" specular="0.1" shininess="0.1"/>
    <material name="rod_mat" rgba="0.30 0.27 0.24 1" specular="0.3" shininess="0.4"/>
    <material name="bob_mat" rgba="0.86 0.34 0.30 1" specular="0.4" shininess="0.45"/>
  </asset>

  <worldbody>
    <light pos="0 0 12" dir="-0.30 0.55 -1" directional="true" castshadow="true"
           diffuse="0.85 0.82 0.78" specular="0.15 0.15 0.15"/>
    <light pos="0 0 8" dir="0.40 -0.30 -1" directional="true" castshadow="false"
           diffuse="0.28 0.28 0.34" specular="0 0 0"/>

    <geom name="floor" type="plane" size="40 40 0.1" material="floor_mat"/>
    <geom type="box" pos="0 0 0.025" size="0.08 0.08 0.025" material="base_mat"/>

    <body name="link0" pos="0 0 0.05">
      <joint name="h0" type="hinge" axis="0 1 0" stiffness="1.8" damping="0.12"/>
      <geom type="capsule" fromto="0 0 0  0 0 0.20" size="0.010" material="rod_mat" mass="0.04"/>
      <geom type="sphere" pos="0 0 0.20" size="0.038" mass="0.12" material="bob_mat"/>
      <body name="link1" pos="0 0 0.20">
        <joint name="h1" type="hinge" axis="0 1 0" stiffness="1.8" damping="0.12"/>
        <geom type="capsule" fromto="0 0 0  0 0 0.20" size="0.010" material="rod_mat" mass="0.04"/>
        <geom type="sphere" pos="0 0 0.20" size="0.038" mass="0.12" material="bob_mat"/>
        <body name="link2" pos="0 0 0.20">
          <joint name="h2" type="hinge" axis="0 1 0" stiffness="1.8" damping="0.12"/>
          <geom type="capsule" fromto="0 0 0  0 0 0.20" size="0.010" material="rod_mat" mass="0.04"/>
          <geom type="sphere" pos="0 0 0.20" size="0.038" mass="0.12" material="bob_mat"/>
          <body name="link3" pos="0 0 0.20">
            <joint name="h3" type="hinge" axis="0 1 0" stiffness="1.8" damping="0.12"/>
            <geom type="capsule" fromto="0 0 0  0 0 0.20" size="0.010" material="rod_mat" mass="0.04"/>
            <geom type="sphere" pos="0 0 0.20" size="0.042" mass="0.14" material="bob_mat"/>
          </body>
        </body>
      </body>
    </body>

    <camera name="cam" pos="0.75 -2.20 0.85" fovy="40"
            xyaxes="0.985 0.158 0   -0.011 0.069 0.998"/>
  </worldbody>
</mujoco>
