<mujoco model="pendulum_waves">
  <compiler angle="radian" coordinate="local" autolimits="true"/>
  <option timestep="0.001" gravity="0 0 -9.81" integrator="implicitfast"/>

  <visual>
    <headlight diffuse="0 0 0" ambient="0.50 0.48 0.55" specular="0 0 0"/>
    <rgba haze="0.94 0.91 0.90 1"/>
    <global azimuth="120" elevation="-12" offwidth="1920" offheight="1080" fovy="38"/>
    <quality shadowsize="8192" offsamples="8"/>
    <map shadowclip="5" shadowscale="0.7"/>
  </visual>

  <asset>
    <texture type="skybox" builtin="flat"
             rgb1="0.74 0.68 0.86" rgb2="0.74 0.68 0.86"
             width="512" height="512" mark="none" markrgb="0 0 0"/>
    <material name="floor_mat"  rgba="0.94 0.91 0.90 1" specular="0" shininess="0"/>
    <material name="frame_wood" rgba="0.78 0.65 0.40 1" specular="0.12" shininess="0.15"/>
    <material name="rod_mat"    rgba="0.30 0.27 0.24 1" specular="0" shininess="0"/>
    <material name="bob_warm"   rgba="0.92 0.74 0.36 1" specular="0.4" shininess="0.55"/>
  </asset>

  <worldbody>
    <light pos="0 0 12" dir="-0.30 0.55 -1" directional="true" castshadow="true"
           diffuse="0.85 0.82 0.78" specular="0.15 0.15 0.15"/>
    <light pos="0 0 8" dir="0.40 -0.30 -1" directional="true" castshadow="false"
           diffuse="0.28 0.28 0.34" specular="0 0 0"/>

    <geom name="floor" type="plane" size="40 40 0.1" material="floor_mat"/>

    <geom type="box" size="0.035 0.035 1.00"
          pos="-1.0500 0 1.0000" material="frame_wood"/>
    <geom type="box" size="0.035 0.035 1.00"
          pos=" 1.0500 0 1.0000" material="frame_wood"/>
    <geom name="bar" type="capsule" fromto="-1.0500 0 2.0000  1.0500 0 2.0000" size="0.012"
          material="frame_wood"/>

    <body name="p0" pos="-0.9500 0 2.0000">
      <joint name="j0" type="hinge" axis="1 0 0" damping="0.0008"/>
      <geom type="capsule" fromto="0 0 0  0 0 -0.3578" size="0.0035"
            material="rod_mat" contype="0" conaffinity="0"/>
      <geom type="sphere" pos="0 0 -0.3578" size="0.022" mass="0.020"
            material="bob_warm" contype="0" conaffinity="0"/>
    </body>
    <body name="p1" pos="-0.8038 0 2.0000">
      <joint name="j1" type="hinge" axis="1 0 0" damping="0.0008"/>
      <geom type="capsule" fromto="0 0 0  0 0 -0.3308" size="0.0035"
            material="rod_mat" contype="0" conaffinity="0"/>
      <geom type="sphere" pos="0 0 -0.3308" size="0.022" mass="0.020"
            material="bob_warm" contype="0" conaffinity="0"/>
    </body>
    <body name="p2" pos="-0.6577 0 2.0000">
      <joint name="j2" type="hinge" axis="1 0 0" damping="0.0008"/>
      <geom type="capsule" fromto="0 0 0  0 0 -0.3068" size="0.0035"
            material="rod_mat" contype="0" conaffinity="0"/>
      <geom type="sphere" pos="0 0 -0.3068" size="0.022" mass="0.020"
            material="bob_warm" contype="0" conaffinity="0"/>
    </body>
    <body name="p3" pos="-0.5115 0 2.0000">
      <joint name="j3" type="hinge" axis="1 0 0" damping="0.0008"/>
      <geom type="capsule" fromto="0 0 0  0 0 -0.2853" size="0.0035"
            material="rod_mat" contype="0" conaffinity="0"/>
      <geom type="sphere" pos="0 0 -0.2853" size="0.022" mass="0.020"
            material="bob_warm" contype="0" conaffinity="0"/>
    </body>
    <body name="p4" pos="-0.3654 0 2.0000">
      <joint name="j4" type="hinge" axis="1 0 0" damping="0.0008"/>
      <geom type="capsule" fromto="0 0 0  0 0 -0.2659" size="0.0035"
            material="rod_mat" contype="0" conaffinity="0"/>
      <geom type="sphere" pos="0 0 -0.2659" size="0.022" mass="0.020"
            material="bob_warm" contype="0" conaffinity="0"/>
    </body>
    <body name="p5" pos="-0.2192 0 2.0000">
      <joint name="j5" type="hinge" axis="1 0 0" damping="0.0008"/>
      <geom type="capsule" fromto="0 0 0  0 0 -0.2485" size="0.0035"
            material="rod_mat" contype="0" conaffinity="0"/>
      <geom type="sphere" pos="0 0 -0.2485" size="0.022" mass="0.020"
            material="bob_warm" contype="0" conaffinity="0"/>
    </body>
    <body name="p6" pos="-0.0731 0 2.0000">
      <joint name="j6" type="hinge" axis="1 0 0" damping="0.0008"/>
      <geom type="capsule" fromto="0 0 0  0 0 -0.2327" size="0.0035"
            material="rod_mat" contype="0" conaffinity="0"/>
      <geom type="sphere" pos="0 0 -0.2327" size="0.022" mass="0.020"
            material="bob_warm" contype="0" conaffinity="0"/>
    </body>
    <body name="p7" pos="0.0731 0 2.0000">
      <joint name="j7" type="hinge" axis="1 0 0" damping="0.0008"/>
      <geom type="capsule" fromto="0 0 0  0 0 -0.2184" size="0.0035"
            material="rod_mat" contype="0" conaffinity="0"/>
      <geom type="sphere" pos="0 0 -0.2184" size="0.022" mass="0.020"
            material="bob_warm" contype="0" conaffinity="0"/>
    </body>
    <body name="p8" pos="0.2192 0 2.0000">
      <joint name="j8" type="hinge" axis="1 0 0" damping="0.0008"/>
      <geom type="capsule" fromto="0 0 0  0 0 -0.2054" size="0.0035"
            material="rod_mat" contype="0" conaffinity="0"/>
      <geom type="sphere" pos="0 0 -0.2054" size="0.022" mass="0.020"
            material="bob_warm" contype="0" conaffinity="0"/>
    </body>
    <body name="p9" pos="0.3654 0 2.0000">
      <joint name="j9" type="hinge" axis="1 0 0" damping="0.0008"/>
      <geom type="capsule" fromto="0 0 0  0 0 -0.1935" size="0.0035"
            material="rod_mat" contype="0" conaffinity="0"/>
      <geom type="sphere" pos="0 0 -0.1935" size="0.022" mass="0.020"
            material="bob_warm" contype="0" conaffinity="0"/>
    </body>
    <body name="p10" pos="0.5115 0 2.0000">
      <joint name="j10" type="hinge" axis="1 0 0" damping="0.0008"/>
      <geom type="capsule" fromto="0 0 0  0 0 -0.1826" size="0.0035"
            material="rod_mat" contype="0" conaffinity="0"/>
      <geom type="sphere" pos="0 0 -0.1826" size="0.022" mass="0.020"
            material="bob_warm" contype="0" conaffinity="0"/>
    </body>
    <body name="p11" pos="0.6577 0 2.0000">
      <joint name="j11" type="hinge" axis="1 0 0" damping="0.0008"/>
      <geom type="capsule" fromto="0 0 0  0 0 -0.1726" size="0.0035"
            material="rod_mat" contype="0" conaffinity="0"/>
      <geom type="sphere" pos="0 0 -0.1726" size="0.022" mass="0.020"
            material="bob_warm" contype="0" conaffinity="0"/>
    </body>
    <body name="p12" pos="0.8038 0 2.0000">
      <joint name="j12" type="hinge" axis="1 0 0" damping="0.0008"/>
      <geom type="capsule" fromto="0 0 0  0 0 -0.1634" size="0.0035"
            material="rod_mat" contype="0" conaffinity="0"/>
      <geom type="sphere" pos="0 0 -0.1634" size="0.022" mass="0.020"
            material="bob_warm" contype="0" conaffinity="0"/>
    </body>
    <body name="p13" pos="0.9500 0 2.0000">
      <joint name="j13" type="hinge" axis="1 0 0" damping="0.0008"/>
      <geom type="capsule" fromto="0 0 0  0 0 -0.1549" size="0.0035"
            material="rod_mat" contype="0" conaffinity="0"/>
      <geom type="sphere" pos="0 0 -0.1549" size="0.022" mass="0.020"
            material="bob_warm" contype="0" conaffinity="0"/>
    </body>

    <!-- Camera: 3/4 view from above-and-front.  World +x reads as image right
         (so bobs fan across the screen horizontally), and the pendulum swing
         in y now reads as up-down motion across the screen — that's what
         makes the wave pattern visible. -->
    <camera name="cam" pos="0 -1.8 3.6" fovy="40"
            xyaxes="1 0 0   0 0.688 0.726"/>
  </worldbody>
</mujoco>
