<mujoco model="skater_pulling_arms_in">
  <compiler angle="radian" coordinate="local" autolimits="true"/>
  <option timestep="0.001" gravity="0 0 -9.81" integrator="implicitfast"/>

  <visual>
    <headlight diffuse="0 0 0" ambient="0.50 0.48 0.55" specular="0 0 0"/>
    <rgba haze="0.94 0.91 0.90 1"/>
    <global azimuth="120" elevation="-15" offwidth="1920" offheight="1080" fovy="40"/>
    <quality shadowsize="8192" offsamples="8"/>
    <map shadowclip="6" shadowscale="0.7"/>
  </visual>

  <asset>
    <texture type="skybox" builtin="flat"
             rgb1="0.74 0.68 0.86" rgb2="0.74 0.68 0.86"
             width="512" height="512" mark="none" markrgb="0 0 0"/>
    <material name="floor_mat" rgba="0.94 0.91 0.90 1" specular="0" shininess="0"/>
    <material name="wood" rgba="0.93 0.82 0.58 1" specular="0.1" shininess="0.1"/>
    <material name="hub_mat" rgba="0.22 0.22 0.24 1" specular="0.4" shininess="0.5"/>
    <material name="rod_mat" rgba="0.82 0.58 0.30 1" specular="0.15" shininess="0.2"/>
    <material name="bob_red" rgba="0.86 0.34 0.30 1" specular="0.35" shininess="0.4"/>
    <material name="bob_blue" rgba="0.30 0.50 0.78 1" specular="0.35" shininess="0.4"/>
  </asset>

  <worldbody>
    <light pos="0 0 12" dir="-0.30 0.55 -1" directional="true" castshadow="true"
           diffuse="0.85 0.82 0.78" specular="0.15 0.15 0.15"/>
    <light pos="0 0 8" dir="0.40 -0.30 -1" directional="true" castshadow="false"
           diffuse="0.28 0.28 0.34" specular="0 0 0"/>

    <geom name="floor" type="plane" size="40 40 0.1" material="floor_mat"/>

    <geom type="cylinder" fromto="0 0 0  0 0 0.220" size="0.04" material="wood"
          contype="0" conaffinity="0"/>

    <!-- Single connected rotor: hub + full guide rods + two sliding blocks -->
    <body name="rotor" pos="0 0 0.220">
      <joint name="hub_spin" type="hinge" axis="0 0 1" damping="0.0002"/>

      <!-- Small central hub -->
      <geom name="hub" type="cylinder" size="0.035 0.025"
            material="hub_mat" mass="0.04" contype="0" conaffinity="0"/>

      <!-- Fixed guide rods through hub — always span the full arm length -->
      <geom name="rod_pos" type="capsule"
            fromto="0.035 0 0  0.680 0 0" size="0.013"
            material="rod_mat" contype="0" conaffinity="0"/>
      <geom name="rod_neg" type="capsule"
            fromto="-0.035 0 0  -0.680 0 0" size="0.013"
            material="rod_mat" contype="0" conaffinity="0"/>

      <!-- +x sliding mass: body origin = mass center, rides on the rod -->
      <body name="mass_pos">
        <joint name="slide_pos" type="slide" axis="1 0 0"
               range="0.140 0.600"
               stiffness="12.0" springref="0.140" damping="2.5"/>
        <!-- Sleeve segment: rod visually passes through the block -->
        <geom name="sleeve_pos" type="capsule"
              fromto="-0.050 0 0  0.050 0 0" size="0.012"
              material="rod_mat" contype="0" conaffinity="0"/>
        <geom name="block_pos" type="box" size="0.045 0.045 0.034"
              mass="0.7" material="bob_red" contype="0" conaffinity="0"/>
      </body>

      <!-- -x sliding mass: mirrored slide axis -->
      <body name="mass_neg">
        <joint name="slide_neg" type="slide" axis="-1 0 0"
               range="0.140 0.600"
               stiffness="12.0" springref="0.140" damping="2.5"/>
        <geom name="sleeve_neg" type="capsule"
              fromto="-0.050 0 0  0.050 0 0" size="0.012"
              material="rod_mat" contype="0" conaffinity="0"/>
        <geom name="block_neg" type="box" size="0.045 0.045 0.034"
              mass="0.7" material="bob_blue" contype="0" conaffinity="0"/>
      </body>
    </body>

    <camera name="cam" pos="0.7 -1.0 0.75" fovy="40"
            xyaxes="0.857 0.514 0  -0.184 0.307 0.934"/>
  </worldbody>
</mujoco>
