<mujoco model="truss_collapse">
  <!-- 4-bar trapezoid + diagonal C-B (removed at t≈0.8 s in render). -->
  <compiler angle="radian" coordinate="local" autolimits="true"/>
  <option timestep="0.001" gravity="0 0 -9.81" integrator="implicitfast"
          impratio="3" cone="elliptic"/>

  <visual>
    <headlight diffuse="0 0 0" ambient="0.50 0.48 0.55" specular="0 0 0"/>
    <rgba haze="0.94 0.91 0.90 1"/>
    <global azimuth="120" elevation="-15" offwidth="1920" offheight="1080" fovy="38"/>
    <quality shadowsize="8192" offsamples="8"/>
    <map shadowclip="6" shadowscale="0.7"/>
  </visual>

  <asset>
    <texture type="skybox" builtin="flat"
             rgb1="0.74 0.68 0.86" rgb2="0.74 0.68 0.86"
             width="512" height="512" mark="none" markrgb="0 0 0"/>
    <material name="floor_mat" rgba="0.94 0.91 0.90 1" specular="0" shininess="0"/>
    <material name="support_mat" rgba="0.30 0.27 0.24 1" specular="0.1" shininess="0.1"/>
    <material name="bar_mat" rgba="0.42 0.44 0.46 1" specular="0.15" shininess="0.15"/>
    <material name="joint_pin" rgba="0.22 0.20 0.22 1" specular="0.25" shininess="0.25"/>
    <material name="payload" rgba="0.86 0.34 0.30 1" specular="0.35" shininess="0.4"/>
  </asset>

  <default>
    <geom contype="0" conaffinity="0" friction="0.6 0.04 0.001"/>
  </default>

  <worldbody>
    <light pos="0 0 12" dir="-0.30 0.55 -1" directional="true" castshadow="true"
           diffuse="0.85 0.82 0.78" specular="0.15 0.15 0.15"/>
    <light pos="0 0 8" dir="0.40 -0.30 -1" directional="true" castshadow="false"
           diffuse="0.28 0.28 0.34" specular="0 0 0"/>

    <geom name="floor" type="plane" size="40 40 0.1" material="floor_mat"
          contype="1" conaffinity="1"/>

    <geom type="box" size="0.05 0.06 0.0400" pos="-0.5000 0 0.0400"
          material="support_mat"/>
    <geom type="box" size="0.05 0.06 0.0400" pos="0.5000 0 0.0400"
          material="support_mat"/>

    <geom name="bar_AB" type="capsule"
          fromto="-0.5000 0 0.0500  0.5000 0 0.0500"
          size="0.013" material="bar_mat"/>

    <!-- Open chain A-C-D-B with hinges at A, C, D -->
    <body name="leg_AC" pos="-0.5000 0 0.0500">
      <joint name="h_A" type="hinge" axis="0 1 0" damping="0.35"/>
      <geom name="bar_AC" type="capsule" fromto="0 0 0  0.1500 0 0.5000" size="0.013"
            mass="0.06" material="bar_mat"/>
      <geom type="sphere" size="0.016" material="joint_pin" mass="0.008"
            contype="0" conaffinity="0"/>

      <body name="coupler" pos="0.1500 0 0.5000">
        <joint name="h_C" type="hinge" axis="0 1 0" damping="0.35"/>
        <geom name="bar_CD" type="capsule" fromto="0 0 0  0.7000 0 0.0000" size="0.013"
              mass="0.042" material="bar_mat"/>
        <geom type="sphere" size="0.016" material="joint_pin" mass="0.008"
              contype="0" conaffinity="0"/>
        <site name="s_C" pos="0 0 0" size="0.001"/>
        <geom name="bar_CB" type="capsule" fromto="0 0 0  0.8500 0 -0.5000" size="0.013"
              mass="0.001" material="bar_mat" contype="0" conaffinity="0"/>
        <geom name="load" type="box"
              pos="0.4300 0 0.0700"
              size="0.065 0.035 0.065" mass="1.05" material="payload"
              contype="1" conaffinity="1"
              solref="0.003 1" solimp="0.95 0.99 0.001"/>

        <body name="leg_DB" pos="0.7000 0 0.0000">
          <joint name="h_D" type="hinge" axis="0 1 0" damping="0.35"/>
          <geom name="bar_BD" type="capsule" fromto="0 0 0  0.1500 0 -0.5000" size="0.013"
                mass="0.06" material="bar_mat"/>
          <geom type="sphere" size="0.016" material="joint_pin" mass="0.008"
                contype="0" conaffinity="0"/>
          <geom type="sphere" pos="0.1500 0 -0.5000" size="0.016" material="joint_pin"
                mass="0.008" contype="0" conaffinity="0"/>
        </body>
      </body>
    </body>

    <!-- Fixed pin at support B (closure point for the open chain) -->
    <body name="anchor_B" pos="0.5000 0 0.0500">
      <geom type="sphere" size="0.016" material="joint_pin" mass="0.001"
            contype="0" conaffinity="0"/>
      <site name="s_B" pos="0 0 0" size="0.001"/>
    </body>

    <camera name="cam" pos="0.00 -1.55 0.28" fovy="44"
            xyaxes="1 0 0  0 0 1"/>
  </worldbody>

  <tendon>
    <!-- Critical diagonal C-B: triangulates frame until removed at render time. -->
    <spatial name="diag_CB" stiffness="6500.0" damping="2.5"
             springlength="0.98615" width="0.001"
             rgba="0.42 0.44 0.46 0" limited="false">
      <site site="s_C"/>
      <site site="s_B"/>
    </spatial>
  </tendon>

  <equality>
    <connect name="pin_B" body1="leg_DB" body2="anchor_B"
             anchor="0.1500 0 -0.5000"
             solref="0.002 1" solimp="0.99 0.999 0.0001"/>
  </equality>
</mujoco>
